Workbook

Sheet Respuestas de formulario 1
A1: Marca temporal | B1: Puntuación | C1: N° PETICIÓN | D1: Nombre Técnico | E1: SUPERVISOR | F1: Se ejecuto la actividad | G1: Se concreta auditoria? | H1: Motivo de la derivación | I1: Auditoria | J1: Actividad | K1: Instala drop con soportes | L1: DIRECCIÓN (Calle - Numero) | M1: Instala Pasa-muros | N1: Roseta Óptica en norma y atornillada | O1: Repetidor Cableado | P1: Cantidad Decodificadores | Q1: Capacitación al Cliente | R1: Deja Área de Trabajo Limpio | S1: Quien recibe en domicilio | T1: Nota de Estética del cableado | U1: Fotografía Módem | V1: Fotografía Roseta Óptica Atornillada | W1: Fotografías Pasa-muros | X1: Fotografías | Y1: Estado Auditoria | Z1: Técnico cumple correctamente con su función? | AA1: Con que nota se evalúa al técnico | AB1: Observaciones (detallar observaciones) | AC1: Utiliza OneClick para realizar limpieza a conectores | AD1: Drop se encuentra encuentra dentro de norma de instalaciones | AE1: Reutiliza Instalación | AF1: Utiliza Alcohol isopropilico | AG1: Reutiliza Instalación de otra compañía | AH1: Se llevó a cabo la mesa de trabajo. | AI1: Se cerró el proceso con el técnico? | AJ1: Observaciones
A2: 46238.965 | B2: 0 | C2: 1-3MZZBB80 | D2: FERNANDO ALEXIS SANCHEZ ZAMORA | E2: JULIO CABRERA | F2: Si | G2: Si | I2: En Conjunto con Técnico | J2: Migracion | K2: NO | L2: Puerto de palos 38 | M2: NO | N2: SI | O2: NO | P2: Solo internet | Q2: SI | R2: SI | S2: Michelle Hernandez | T2: 4 | U2: https://drive.google.com/open?id=1eLiAAX-JitqlZ_Uy1Wtqd-BaYuer__sy | V2: https://drive.google.com/open?id=1M5W9rcXFlyTmREE9KJFCGx1z3V3z78jK | W2: https://drive.google.com/open?id=1KsGJ-oxout_7n7kZQlBeuIYexSo59vI8 | X2: https://drive.google.com/open?id=1ugWq8gxEvzZ3Zrq6Vt4RfT-zPz7aB4ol | Y2: Si Cumple | Z2: Si Cumple | AA2: 6 | AB2: Drop sin soportes , faltó pasamuro. | AH2: =IFERROR(VLOOKUP(Form_Responses[[#This Row],[Nombre Técnico]],'masa de trabajo'!$B:$C,2,0),"") -> SI | AI2: =VLOOKUP(Form_Responses[[#This Row],[Nombre Técnico]],'masa de trabajo'!$B:$E,3,0) -> SI | AJ2: =VLOOKUP(Form_Responses[[#This Row],[Nombre Técnico]],'masa de trabajo'!$B:$E,4,0) -> -
A3: 46241.445 | B3: 0 | C3: 1-3NOSIUO9 | D3: ALMAZABAL TORO ALEJANDRO ADRIAN | E3: JULIO CABRERA | F3: Si | G3: Si | I3: En Conjunto con Técnico | J3: Migracion | K3: NO | L3: Lago Zenteno 1530 | M3: NO | N3: SI | Q3: SI | R3: SI | S3: Isabel Barraza | T3: 4 | U3: https://drive.google.com/open?id=12iqDQ8PRPzKO0ZtxepVFD_lo9Oak1i0A | V3: https://drive.google.com/open?id=1kU25jEZiCTDYyeWXk7c2rwKjJW51ip9r | X3: https://drive.google.com/open?id=1JiROAHGcZpKBb8AYqsKEkaQIUwITYdd- | Y3: Si Cumple | Z3: Si Cumple | AA3: 9 | AB3: Instalación interior edificio no lleva pasamuro. | AH3: =IFERROR(VLOOKUP(Form_Responses[[#This Row],[Nombre Técnico]],'masa de trabajo'!$B:$C,2,0),"") -> SI | AI3: =VLOOKUP(Form_Responses[[#This Row],[Nombre Técnico]],'masa de trabajo'!$B:$E,3,0) -> SI | AJ3: =VLOOKUP(Form_Responses[[#This Row],[Nombre Técnico]],'masa de trabajo'!$B:$E,4,0) -> Auque se nota una mejora, se realizara evantualemete seguimiento a los trabajos
A4: 46241.45 | B4: 0 | C4: 1-3N1EXH6Z | D4: ALMAZABAL TORO ALEJANDRO ADRIAN | E4: JULIO CABRERA | F4: Si | G4: Si | I4: En Conjunto con Técnico | J4: Instalacion | K4: NO | L4: Variante Agua Santa 1400 | M4: NO | N4: SI | P4: 2 | Q4: SI | R4: SI | S4: Doris Perez | T4: 4 | U4: https://drive.google.com/open?id=1fjU3RvPo3EX5BcpGMOPN3bz-u6iU2Q4I | V4: https://drive.google.com/open?id=17lXQX1mTuaoqy9ifOYdLztSv-UjgbzJ7 | X4: https://drive.google.com/open?id=1ecPUCwGEQYjplmfEYtFc221G1_0qA_T9 | Y4: Si Cumple | Z4: Si Cumple | AA4: 9 | AB4: Instalación por ductos , no lleva pasamuros. | AH4: =IFERROR(VLOOKUP(Form_Responses[[#This Row],[Nombre Técnico]],'masa de trabajo'!$B:$C,2,0),"") -> SI | AI4: =VLOOKUP(Form_Responses[[#This Row],[Nombre Técnico]],'masa de trabajo'!$B:$E,3,0) -> SI | AJ4: =VLOOKUP(Form_Responses[[#This Row],[Nombre Técnico]],'masa de trabajo'!$B:$E,4,0) -> Auque se nota una mejora, se realizara evantualemete seguimiento a los trabajos
A5: 46243.751 | B5: 0 | C5: 1-3N1OD3VC | D5: LUIS ROBERTO QUIROGA SEGUEL | E5: DANILO OJEDA | F5: Si | G5: Si | I5: En Conjunto con Técnico | J5: Modificacion | K5: NO | L5: Pasaje diesiseis 4576, Quinta Normal | M5: SI | N5: NO | P5: 3 | Q5: SI | R5: SI | S5: Alvara Ceron | T5: 3 | U5: https://drive.google.com/open?id=1xRoqVLV7TnRBkCtOSTEgYjJzWnnxmSh9 | V5: https://drive.google.com/open?id=1HftL8nuwMbjUi_N_uPN54iieHc1SNhZ7 | W5: https://drive.google.com/open?id=19_stumq0aaIfxRLjsrQcctleoeYxzyCD | X5: https://drive.google.com/open?id=1IfDHf1Ap0Yyo32pZFKUGiyCTMwkquF8X | Y5: Si Cumple | Z5: Si Cumple | AA5: 7 | AB5: No instala soporte drop, la capacitación sobre el uso del control, cliente manifestó que su hija lo vería después, ella no quedo clara, roseta instalada sobre 30 centímetros a petición de cliente. | AH5: =IFERROR(VLOOKUP(Form_Responses[[#This Row],[Nombre Técnico]],'masa de trabajo'!$B:$C,2,0),"") -> SI | AI5: =VLOOKUP(Form_Responses[[#This Row],[Nombre Técnico]],'masa de trabajo'!$B:$E,3,0) -> - | AJ5: =VLOOKUP(Form_Responses[[#This Row],[Nombre Técnico]],'masa de trabajo'!$B:$E,4,0) -> -
A6: 46244.902 | B6: 0 | C6: 1-3N3QTY2X | D6: BENJAMIN ALEJANDRO PEREZ POVEDA | E6: ROLANDO MOTOYA | F6: Si | G6: Si | H6: Reparacion | I6: En Conjunto con Técnico | J6: Reparacion | K6: SI | L6: MEXICO 1163 | M6: SI | N6: SI | O6: NO | P6: 1 | Q6: SI | R6: SI | S6: DANES AMADOR SABA MIOSOTI | T6: 4 | U6: https://drive.google.com/open?id=1Ct3HMcGgtkRN1ays-ZSxeiG2cr3txlbM | V6: https://drive.google.com/open?id=1cAg185xHKS5Jvh4Ti7ijYMyyD7sf934v | W6: https://drive.google.com/open?id=1FMSZOl4jm7NCv0YV2I76OTv48kR4YjC0 | X6: https://drive.google.com/open?id=1n6c6KG1MLLnZmc2xervPDiZcGEiOiCyi | Y6: No Cumple | Z6: No Cumple | AA6: 7 | AB6: Tecnico no utiliza one click segun procedimiento Cliente en reparacion representa problemas de inestabilidad en navegación ,desconexiones y lentitud en descargas Se verifica cobertura con app wifi analizar encontrando problemas de cobertura( -63dbm) ,se solicita repetidor wifi como mejoramiento de servicio en petición 1-3N4VBVMB quedando con -44 dbm -50 dbm y -38 dbm..veloc.en app marca 544 Mbps en domicilio ..se prueba conexiones con cliente quedando conforme . Nota se debió solicitar repetidor desde la.peticion de instalacion por técnico instalador de otras eps | AH6: =IFERROR(VLOOKUP(Form_Responses[[#This Row],[Nombre Técnico]],'masa de trabajo'!$B:$C,2,0),"") -> SI | AI6: =VLOOKUP(Form_Responses[[#This Row],[Nombre Técnico]],'masa de trabajo'!$B:$E,3,0) -> SI | AJ6: =VLOOKUP(Form_Responses[[#This Row],[Nombre Técnico]],'masa de trabajo'!$B:$E,4,0) -> -
A7: 46245.54 | B7: 0 | C7: 1-3N1EXTB4 | D7: JORGE LUIS REYES TOLOZA | E7: DANILO OJEDA | F7: Si | G7: Si | I7: En Conjunto con Técnico | J7: Instalacion | K7: NO | L7: Alsino 4691 torre B dpto 54, Quinta Normal | N7: SI | Q7: No | R7: SI | S7: MINERVA DEL CARMEN LLANOS SANHUEZA | T7: 3 | U7: https://drive.google.com/open?id=1YKKAkGD4EQW-dPfPbHSEbpsBuE7HuDQ2 | V7: https://drive.google.com/open?id=1PhtfDwK7_KSjjmrTzZRu8eaRaS76mByG | X7: https://drive.google.com/open?id=1qvV5AHtlp5_I4SZ6Ec-EBbt55zMespJ8 | Y7: Si Cumple | Z7: No Cumple | AA7: 5 | AB7: No limpia fibra con alcohol isopropilico, no capacita a cliente | AH7: =IFERROR(VLOOKUP(Form_Responses[[#This Row],[Nombre Técnico]],'masa de trabajo'!$B:$C,2,0),"") -> SI | AI7: =VLOOKUP(Form_Responses[[#This Row],[Nombre Técnico]],'masa de trabajo'!$B:$E,3,0) -> - | AJ7: =VLOOKUP(Form_Responses[[#This Row],[Nombre Técnico]],'masa de trabajo'!$B:$E,4,0) -> -
A8: 46245.569 | B8: 0 | C8: 1-3N4ZJYPV | D8: EUDIS JESUS ALDAMA MARIN | E8: DANILO OJEDA | F8: Si | G8: Si | I8: En Conjunto con Técnico | J8: Instalacion | K8: NO | L8: Freirina 2024, Independencia | M8: NO | N8: NO | P8: 2 | Q8: SI | R8: SI | S8: Guillermina Retamal Barrera | T8: 4 | U8: https://drive.google.com/open?id=1WwnXsHKOqdcxhVKy7K78PfZqcdpIXWPD | V8: https://drive.google.com/open?id=1a49an2Uxx5--xhVG5AJh9DzmiTTr-8zE | W8: https://drive.google.com/open?id=1cFFm7QlOqMpnPhvBRjg5rcmtQTiDSSzl | X8: https://drive.google.com/open?id=1hUQTu7-Yh2d6RG0qCUag9TKWRnYl2eLN | Y8: Si Cumple | Z8: Si Cumple | AA8: 9 | AB8: No instala pasa muros, cliente posee adaptador de red para decodificador por cobertura | AH8: =IFERROR(VLOOKUP(Form_Responses[[#This Row],[Nombre Técnico]],'masa de trabajo'!$B:$C,2,0),"") -> SI | AI8: =VLOOKUP(Form_Responses[[#This Row],[Nombre Técnico]],'masa de trabajo'!$B:$E,3,0) -> SI | AJ8: =VLOOKUP(Form_Responses[[#This Row],[Nombre Técnico]],'masa de trabajo'!$B:$E,4,0) -> -
A9: 46246.746 | B9: 0 | C9: 1-3N38LO21 | D9: LUIS ROBERTO QUIROGA SEGUEL | E9: DANILO OJEDA | F9: Si | G9: Si | I9: En Conjunto con Técnico | J9: Instalacion | K9: NO | L9: Neuquen 1658, Quinta Normal | M9: SI | N9: SI | Q9: SI | R9: SI | S9: Jonhy Arevalo | T9: 4 | U9: https://drive.google.com/open?id=1nF8b6PoUw5jmaMs3GmfPKH9f_sIPQnnU | V9: https://drive.google.com/open?id=1bm95wbg0W4QfOhTQ-l3iSNpuXZbayYdA | W9: https://drive.google.com/open?id=13gcBcAKvwZidaHyvwSsOryf5yBWRFTBU | X9: https://drive.google.com/open?id=1_qsmYESpm1TZYZBTcSA0bVI1OVnaOqPZ | Y9: Si Cumple | Z9: Si Cumple | AA9: 8 | AB9: No limpia fibra con alcohol isopropilico fibra | AH9: =IFERROR(VLOOKUP(Form_Responses[[#This Row],[Nombre Técnico]],'masa de trabajo'!$B:$C,2,0),"") -> SI | AI9: =VLOOKUP(Form_Responses[[#This Row],[Nombre Técnico]],'masa de trabajo'!$B:$E,3,0) -> - | AJ9: =VLOOKUP(Form_Responses[[#This Row],[Nombre Técnico]],'masa de trabajo'!$B:$E,4,0) -> -
A10: 46247.535 | B10: 0 | C10: 1-3N5HPGPG | D10: LUIS ROBERTO BAIGORRIA CORDOVA | E10: JULIO CABRERA | F10: Si | G10: Si | I10: En Conjunto con Técnico | J10: Migracion | K10: NO | L10: Jackson 785 torre Y depto. 201 | N10: NO | P10: 2 | Q10: SI | R10: SI | S10: Andrés Díaz y Sra. | T10: 4 | U10: https://drive.google.com/open?id=1CSmuYQmqrvrMUUa4nf16cG0GkGD3SynA | V10: https://drive.google.com/open?id=1C7xbpqRZdhbFYfcF4iO3wNkPMuE8MDbR | X10: https://drive.google.com/open?id=1I5m3DHoB2XXOa5jOrNIsndX1rQFjkuR3 | Y10: Si Cumple | Z10: Si Cumple | AA10: 6 | AB10: Roseta con clavo , pilar del edificio concreto. | AH10: =IFERROR(VLOOKUP(Form_Responses[[#This Row],[Nombre Técnico]],'masa de trabajo'!$B:$C,2,0),"") -> SI | AI10: =VLOOKUP(Form_Responses[[#This Row],[Nombre Técnico]],'masa de trabajo'!$B:$E,3,0) -> SI | AJ10: =VLOOKUP(Form_Responses[[#This Row],[Nombre Técnico]],'masa de trabajo'!$B:$E,4,0) -> -
A11: 46247.719 | B11: 0 | C11: 1-3N6QA80X | D11: MARCO ALEXANDER BENITEZ FERNANDEZ | E11: DANILO OJEDA | F11: Si | G11: Si | I11: En Conjunto con Técnico | J11: Instalacion | K11: NO | L11: Rodolfo Mondolfo 6865, Quinta Normal | M11: SI | N11: NO | Q11: SI | R11: SI | S11: LEONARDO ENRIQUE ROLACK REBOLLEDO | T11: 4 | U11: https://drive.google.com/open?id=1OP1hPRSdOrAR3cXLiyxw1o2ogy31xmuT | V11: https://drive.google.com/open?id=1OujuqSLPbgqHCXkRhnw6h9V5HL8K4Mfe | W11: https://drive.google.com/open?id=1WN_3WV6vkXedBc7VCDP6LUrRSoYcekyB | X11: https://drive.google.com/open?id=1HSK3BJ7Qx0WE7hATyxPl7JT9fsOOK1DZ | Y11: Si Cumple | Z11: Si Cumple | AA11: 10 | AB11: Roseta instalada fuera de norma a petición de cliente, técnico cumple protocolo según informado hoy a todo el plantel en reunión. Queda pendiente auditoria post instalación | AH11: =IFERROR(VLOOKUP(Form_Responses[[#This Row],[Nombre Técnico]],'masa de trabajo'!$B:$C,2,0),"") -> - | AI11: =VLOOKUP(Form_Responses[[#This Row],[Nombre Técnico]],'masa de trabajo'!$B:$E,3,0) -> - | AJ11: =VLOOKUP(Form_Responses[[#This Row],[Nombre Técnico]],'masa de trabajo'!$B:$E,4,0) -> -
A12: 46248.498 | B12: 8 | C12: 1-3N5LOYRR | D12: BRAULIO DANILO DIAZ CORNEJO | E12: JULIO CABRERA | F12: Si | G12: Si | I12: Post Instalacion | J12: Instalacion | K12: SI | L12: San Francisco 32 efif.H | M12: SI | N12: SI | Q12: SI | R12: SI | S12: Graciela Toro | T12: 4 | AB12: Instalación acorde a los procedimientos. | AC12: SI | AD12: SI | AE12: NO | AF12: SI | AG12: NO | AH12: =IFERROR(VLOOKUP(Form_Responses[[#This Row],[Nombre Técnico]],'masa de trabajo'!$B:$C,2,0),"") -> SI | AI12: =VLOOKUP(Form_Responses[[#This Row],[Nombre Técnico]],'masa de trabajo'!$B:$E,3,0) -> SI | AJ12: =VLOOKUP(Form_Responses[[#This Row],[Nombre Técnico]],'masa de trabajo'!$B:$E,4,0) -> -
A13: 46251.615 | B13: 7 | C13: 1-3N2YU675 | D13: ANDRES EDUARDO RODRIGUEZ BERMEDO | E13: DANILO OJEDA | F13: Si | G13: Si | I13: Post Instalacion | J13: Instalacion | K13: SI | L13: Juan Castellon 4081, Quinta Normal | M13: NO | N13: SI | Q13: SI | R13: SI | S13: Victor Yañez | T13: 4 | U13: https://drive.google.com/open?id=13PPlqo63EbZRR7L89FEGqMnXDfQv8n-r | V13: https://drive.google.com/open?id=17d52t5PmTfXPB9_QbA6OqPf9kiImuzOs | W13: https://drive.google.com/open?id=1lDE3Am1y1Mw5GWKg_p9mLlaSQGqGgcXE | X13: https://drive.google.com/open?id=1yLJtRMHB524hoNw9q5pILGEoIKZRcthN | Y13: Si Cumple | Z13: Si Cumple | AA13: 8 | AB13: Falta instalar pasa muros, a realizar preguntas a cliente indica haber aclarado las dudas del funcionamiento de forma correcta. | AD13: SI | AE13: NO | AG13: NO | AH13: =IFERROR(VLOOKUP(Form_Responses[[#This Row],[Nombre Técnico]],'masa de trabajo'!$B:$C,2,0),"") -> - | AI13: =VLOOKUP(Form_Responses[[#This Row],[Nombre Técnico]],'masa de trabajo'!$B:$E,3,0) -> - | AJ13: =VLOOKUP(Form_Responses[[#This Row],[Nombre Técnico]],'masa de trabajo'!$B:$E,4,0) -> -
A14: 46251.637 | B14: 1 | C14: 1-3N5H0O6V | D14: ANDRES EDUARDO RODRIGUEZ BERMEDO | E14: DANILO OJEDA | F14: Si | G14: No | I14: Post Instalacion | J14: Instalacion | K14: NO | L14: Rio backer 5632, Quinta Normal | M14: NO | W14: https://drive.google.com/open?id=1MKp2JuTG6FLN0ueQHwBGFuQSkTp8nAcB | X14: https://drive.google.com/open?id=1ECZb-tJbGDX2bKOxosQrZyrzym9KBxL2 | Y14: No Cumple | AA14: 7 | AB14: Sin moradores en domicilio, se evidencia al exterior que no se instala soporte drop, pasa muro instalado sin perforación adecuada | AD14: SI | AE14: NO | AG14: NO | AH14: =IFERROR(VLOOKUP(Form_Responses[[#This Row],[Nombre Técnico]],'masa de trabajo'!$B:$C,2,0),"") -> - | AI14: =VLOOKUP(Form_Responses[[#This Row],[Nombre Técnico]],'masa de trabajo'!$B:$E,3,0) -> - | AJ14: =VLOOKUP(Form_Responses[[#This Row],[Nombre Técnico]],'masa de trabajo'!$B:$E,4,0) -> -
A15: 46252.401 | B15: 9 | C15: 1-3N7Q47LB | D15: JUAN PABLO CACERES SOBARZO | E15: JULIO CABRERA | F15: Si | G15: Si | I15: En Conjunto con Técnico | J15: Migracion | K15: SI | L15: Limonares 399 | N15: SI | Q15: SI | R15: SI | S15: Armando Aravena | T15: 4 | U15: https://drive.google.com/open?id=1Q8vNcuhdAz4joWsuGjDNyWvbEU-wJasi | V15: https://drive.google.com/open?id=1wg6HKw0vboOMxwjSBYFMyCoNLjQe2glH | X15: https://drive.google.com/open?id=1eSKueiB7HIUFlR7czqRlTA0kS2ueqrBv | Y15: Si Cumple | Z15: Si Cumple | AA15: 7 | AB15: Quinto técnico q visita a cliente realizando la instalacion | AC15: SI | AD15: SI | AE15: NO | AF15: SI | AG15: NO | AH15: =IFERROR(VLOOKUP(Form_Responses[[#This Row],[Nombre Técnico]],'masa de trabajo'!$B:$C,2,0),"") -> - | AI15: =VLOOKUP(Form_Responses[[#This Row],[Nombre Técnico]],'masa de trabajo'!$B:$E,3,0) -> - | AJ15: =VLOOKUP(Form_Responses[[#This Row],[Nombre Técnico]],'masa de trabajo'!$B:$E,4,0) -> -
A16: 46252.407 | B16: 7 | C16: 1-3N728IGS | D16: MARIN ORELLANA HERNAN TOMAS | E16: JULIO CABRERA | F16: No | G16: Si | I16: En Conjunto con Técnico | J16: Migracion | K16: SI | L16: Howard 10 | M16: SI | N16: SI | R16: SI | S16: Josefina Astete | T16: 3 | U16: https://drive.google.com/open?id=1VJeC8kIARVBAXRJhaBg-HWlg535qIcyR | V16: https://drive.google.com/open?id=19fja4M2CuNqJHfMYCUY4xkR30-WEqb0T | W16: https://drive.google.com/open?id=1vu-Eev9UKvXcT1YJ8o4Tt9Y-UNmKsclY | X16: https://drive.google.com/open?id=14TYRsLkplV2F4PgRT-NqLGyJXyvd-eYE | Y16: No Cumple | Z16: No Cumple | AA16: 4 | AB16: Orden no se termina problema de dB , técnico sin chicote y falta de guía omologada | AC16: SI | AD16: SI | AE16: NO | AF16: SI | AG16: NO | AH16: =IFERROR(VLOOKUP(Form_Responses[[#This Row],[Nombre Técnico]],'masa de trabajo'!$B:$C,2,0),"") -> - | AI16: =VLOOKUP(Form_Responses[[#This Row],[Nombre Técnico]],'masa de trabajo'!$B:$E,3,0) -> - | AJ16: =VLOOKUP(Form_Responses[[#This Row],[Nombre Técnico]],'masa de trabajo'!$B:$E,4,0) -> -
A17: 46252.439 | B17: 6 | C17: 1-3N3AEQ7U | D17: ALVARO IVAN HERRERA SALINAS | E17: ROLANDO MOTOYA | F17: Si | G17: Si | H17: No hay derivacion | I17: Post Instalacion | J17: Migracion | K17: SI | L17: CATEDRAL 4245 DEPTO 1806 QUINTAN NORMAL | M17: NO | N17: SI | O17: NO | P17: 1 | Q17: No | R17: SI | S17: Omar fuentes | T17: 4 | U17: https://drive.google.com/open?id=1NGfQlyzAFNPmEvRedGZsf2pxU2BwIdRG | V17: https://drive.google.com/open?id=1F83yxxgfvVETwqxnxgE5y_AiZliJsXcR | X17: https://drive.google.com/open?id=1qYERsMZYaQUmpyStu7SKkCOMWtWdsSgj | Y17: Si Cumple | Z17: No Cumple | AA17: 3 | AB17: Se realiza mesa de trabajo informando indicadores operacional Se verifica estado de kit fo con fusionadora encontrado cortadora de fibra en mal estado (falta tornillo) Se informa la importancia de uso one click en terreno y el autochequeo de estado de herramientas Se realiza cambio de cortadora fo en buen estado Ademas de realiza inducción en la entrega de servicios BA-IPTV a nucleo familiar Se realizara seguimiento en terreno para ver su evolución | AC17: No | AD17: SI | AE17: NO | AF17: SI | AG17: NO | AH17: =IFERROR(VLOOKUP(Form_Responses[[#This Row],[Nombre Técnico]],'masa de trabajo'!$B:$C,2,0),"") -> SI | AI17: =VLOOKUP(Form_Responses[[#This Row],[Nombre Técnico]],'masa de trabajo'!$B:$E,3,0) -> SI | AJ17: =VLOOKUP(Form_Responses[[#This Row],[Nombre Técnico]],'masa de trabajo'!$B:$E,4,0) -> -
A18: 46252.569 | B18: 9 | C18: 1-3N94E2SQ | D18: ANDRES EDUARDO RODRIGUEZ BERMEDO | E18: DANILO OJEDA | F18: Si | G18: Si | I18: En Conjunto con Técnico | J18: Migracion | K18: SI | L18: Las Brisas 0804, Recoleta | M18: SI | N18: SI | P18: 2 | Q18: SI | R18: SI | T18: 4 | U18: https://drive.google.com/open?id=15KDgPCFq3sfPmtt5xX54MeAKk9jAUKVI | V18: https://drive.google.com/open?id=1K-xGQrbagf4oW-D6DTh5YlQTXxo403UC | W18: https://drive.google.com/open?id=183JRK--xQWbxG4bkT39QAKRZBROukIUS | X18: https://drive.google.com/open?id=1mT_0H1IUWykWAH58LpNzTr7AD2cAcUIN | Y18: Si Cumple | Z18: Si Cumple | AA18: 9 | AB18: No utiliza one click, cliente conforme | AC18: No | AD18: SI | AE18: NO | AF18: SI | AG18: NO | AH18: =IFERROR(VLOOKUP(Form_Responses[[#This Row],[Nombre Técnico]],'masa de trabajo'!$B:$C,2,0),"") -> - | AI18: =VLOOKUP(Form_Responses[[#This Row],[Nombre Técnico]],'masa de trabajo'!$B:$E,3,0) -> - | AJ18: =VLOOKUP(Form_Responses[[#This Row],[Nombre Técnico]],'masa de trabajo'!$B:$E,4,0) -> -
A19: 46252.579 | B19: 7 | C19: 1-3N9FYITR | D19: BENJAMIN ALEJANDRO PEREZ POVEDA | E19: DANILO OJEDA | F19: Si | G19: Si | I19: Post Instalacion | J19: Instalacion | K19: SI | L19: Coronel de Quintana 428, Independencia | M19: SI | N19: NO | Q19: SI | R19: SI | S19: Miguel Morales | T19: 4 | U19: https://drive.google.com/open?id=12wtFt_wPMKaaRNepL8OxbL8THTvW1rpz | V19: https://drive.google.com/open?id=11NCk5q4BXejTZqIpnwKMwpnaeKMX6obP | W19: https://drive.google.com/open?id=1gY7a-UzONH12AZX1pFa3JgqUrQtTqrdB | X19: https://drive.google.com/open?id=1MnC4kw_8M8wT0rlU24_dE4d_Ds8izo_E | Y19: Si Cumple | Z19: Si Cumple | AA19: 9 | AB19: Roseta fuera de norma a petición de cliente, cliente indica tener problemas de cobertura en un extremo de la casa, se recomienda solicitar repetidor de señal. Instalación de ont ubicada en lugar solicitado por cliente | AD19: SI | AE19: NO | AG19: NO | AH19: =IFERROR(VLOOKUP(Form_Responses[[#This Row],[Nombre Técnico]],'masa de trabajo'!$B:$C,2,0),"") -> SI | AI19: =VLOOKUP(Form_Responses[[#This Row],[Nombre Técnico]],'masa de trabajo'!$B:$E,3,0) -> SI | AJ19: =VLOOKUP(Form_Responses[[#This Row],[Nombre Técnico]],'masa de trabajo'!$B:$E,4,0) -> -
A20: 46252.687 | B20: 8 | C20: 1-3N6CTV6X | D20: LUIS ROBERTO BAIGORRIA CORDOVA | E20: JULIO CABRERA | F20: Si | G20: Si | I20: En Conjunto con Técnico | J20: Migracion | K20: SI | L20: Las Bandurrias 14 | M20: NO | N20: SI | P20: 3 | Q20: SI | R20: SI | T20: 3 | U20: https://drive.google.com/open?id=1-QRkO5YpAkz38prf9Y9Bw8G2tEzPwMOB | V20: https://drive.google.com/open?id=1o_Awr_qJTuOGbya23lKOgpt8Qe3P_lbn | W20: https://drive.google.com/open?id=1_umJ2T0gHpdeAPP5rTnZeH-iCcxKr8BQ | X20: https://drive.google.com/open?id=1TzdMGzyYx5WTozjYRFT2uT4JAqQdxQS9 | Y20: No Cumple | Z20: Si Cumple | AA20: 5 | AB20: Sin pasamuro. | AC20: SI | AD20: SI | AE20: NO | AF20: SI | AG20: NO | AH20: =IFERROR(VLOOKUP(Form_Responses[[#This Row],[Nombre Técnico]],'masa de trabajo'!$B:$C,2,0),"") -> SI | AI20: =VLOOKUP(Form_Responses[[#This Row],[Nombre Técnico]],'masa de trabajo'!$B:$E,3,0) -> SI | AJ20: =VLOOKUP(Form_Responses[[#This Row],[Nombre Técnico]],'masa de trabajo'!$B:$E,4,0) -> -
A21: 46253.409 | B21: 7 | C21: 1-3N9IKPTH | D21: EUDIS JESUS ALDAMA MARIN | E21: ROLANDO MOTOYA | F21: Si | G21: Si | I21: En Conjunto con Técnico | J21: Instalacion | K21: SI | L21: SEVILLA 1403 | M21: SI | N21: SI | O21: NO | P21: 2 | Q21: No | R21: SI | S21: PABLO AURELIO SALDAÑA SANDALLA | T21: 4 | U21: https://drive.google.com/open?id=1po2Usoq_zwtjp4HX44MoKrgj60hav7UT | V21: https://drive.google.com/open?id=1zg-fW83tan2MPbaZRDYhDZomtXiQ6a_c | X21: https://drive.google.com/open?id=19H2kjEx3lwbXwq9aKGzDGUKndI7loOGq | Y21: Si Cumple | Z21: No Cumple | AA21: 5 | AB21: -TECNICO NO UTILIZA ONE CLICK EN TODOS LOS EXTREMOS (JUMPER, CTO) -TECNICO NO CAPACITA SERVICIOS ENTREGADOS EN SU TOTALIDAD | AC21: solo utiliza onde click en roseta optica no en su totalidad | AD21: SI | AE21: NO | AF21: SI | AG21: NO | AH21: =IFERROR(VLOOKUP(Form_Responses[[#This Row],[Nombre Técnico]],'masa de trabajo'!$B:$C,2,0),"") -> SI | AI21: =VLOOKUP(Form_Responses[[#This Row],[Nombre Técnico]],'masa de trabajo'!$B:$E,3,0) -> SI | AJ21: =VLOOKUP(Form_Responses[[#This Row],[Nombre Técnico]],'masa de trabajo'!$B:$E,4,0) -> -
A22: 46254.037 | B22: 9 | C22: 1-3NA4KLE5 | D22: BENJAMIN ALEJANDRO PEREZ POVEDA | E22: DANILO OJEDA | F22: Si | G22: Si | I22: En Conjunto con Técnico | J22: Migracion | L22: Tres de mayo 2685 edificio A dpto 204, independencia | M22: SI | N22: SI | Q22: SI | R22: SI | S22: Aisneis Monte Leon | T22: 4 | U22: https://drive.google.com/open?id=1yh0RqesENYxgJioTiLC6eCgf_izZmf_X | V22: https://drive.google.com/open?id=1UA9NOOfm_FUsc0sAasPLGcVIysznqYuP | W22: https://drive.google.com/open?id=1CN6XrDQMMT9mjrjBPVLl49l3NvnzY1BA | X22: https://drive.google.com/open?id=1IxhwifcGKSW_i_kYEj89Mmqxd2QowsBE | Y22: Si Cumple | Z22: Si Cumple | AA22: 10 | AB22: Auditoria en acompañamiento destacando el uso de herramientas según procedimiento ambos one click | AC22: SI | AD22: SI | AE22: NO | AF22: SI | AG22: NO | AH22: =IFERROR(VLOOKUP(Form_Responses[[#This Row],[Nombre Técnico]],'masa de trabajo'!$B:$C,2,0),"") -> SI | AI22: =VLOOKUP(Form_Responses[[#This Row],[Nombre Técnico]],'masa de trabajo'!$B:$E,3,0) -> SI | AJ22: =VLOOKUP(Form_Responses[[#This Row],[Nombre Técnico]],'masa de trabajo'!$B:$E,4,0) -> -
A23: 46254.793 | B23: 5 | C23: 1-3ND1S289 | D23: VICTOR HUGO HUAMANI | E23: DANILO OJEDA | F23: Si | G23: Si | I23: En Conjunto con Técnico | J23: Modificacion | L23: Recabarren 1584, Independencia | M23: SI | O23: SI | P23: 4 | Q23: SI | R23: SI | S23: Guillermo Puebla | T23: 4 | U23: https://drive.google.com/open?id=1FK9Fm-hJrywhyAtb6KX6xUgQ95_L8DCb | V23: https://drive.google.com/open?id=1c7K51__DBi4S5c0_jXLS82vJyErpdcEl | W23: https://drive.google.com/open?id=175wmetPS8lkwNiPqFoJHg0ClHU-Xlywv | X23: https://drive.google.com/open?id=1ib28GsSsZ6_D2UPnN34V44_vE4lMsjT1 | Y23: Si Cumple | Z23: Si Cumple | AA23: 9 | AB23: Servicio instalado, solo se instala repetidor, si explica el funcionamiento del servicio | AH23: =IFERROR(VLOOKUP(Form_Responses[[#This Row],[Nombre Técnico]],'masa de trabajo'!$B:$C,2,0),"") -> - | AI23: =VLOOKUP(Form_Responses[[#This Row],[Nombre Técnico]],'masa de trabajo'!$B:$E,3,0) -> - | AJ23: =VLOOKUP(Form_Responses[[#This Row],[Nombre Técnico]],'masa de trabajo'!$B:$E,4,0) -> -
A24: 46255.392 | B24: 7 | C24: 1-3NA7AZB4 | D24: VICTOR HUGO HUAMANI | E24: ROLANDO MOTOYA | F24: Si | G24: Si | I24: En Conjunto con Técnico | J24: Instalacion | K24: NO | L24: ZINC 531 | M24: NO | N24: SI | O24: SI | P24: 4 | Q24: SI | R24: SI | S24: EMILCE DEL CARMEN PEREZ PEREZ | T24: 4 | U24: https://drive.google.com/open?id=16MzYbpU1T2i6yGDx9YltGMm5BWUqBy8I | V24: https://drive.google.com/open?id=1pn2uyjHZOjP3PxgwzAGWRciKrmPfAeUp | W24: https://drive.google.com/open?id=1eQH55jHKTpEu_X7G0R-3gu5NlgYfY15z | X24: https://drive.google.com/open?id=1xs2ayM4xI8WCoz54-Cy2bCmBOVwH4tJE | Y24: Si Cumple | Z24: No Cumple | AA24: 4 | AB24: DEBILIDADES-TECNICO NO CUMPLE CON NORMAS DE INSTALACION-NO INSTALA SOPORTE DROP.-NO INSTALA PASAMUROS.-SOLO CAPACITA EN FORMA PARCIAL PRODUCTOS INSTALADOS-NO MUESTRA TEST DE VELOCIDAD Y REALIZA PRUEBAS DE COBERTURA WIFI-TECNICO NFORMA A QUIEN CAPACITA EN DOMICILIO EN TOA-TECNICO SALE 4 VECES DE DOMICILIO DE CLIENTE A BUSCAR MATERIALES O EQUIPOS NOTA: SE CITA A MESA DE TRABAJO PARA REFLEXIONAR EN APLICAR MEJORAS PARA SER APLICADAS EN TERRENO | AC24: SI | AD24: SI | AE24: NO | AF24: SI | AG24: NO | AH24: =IFERROR(VLOOKUP(Form_Responses[[#This Row],[Nombre Técnico]],'masa de trabajo'!$B:$C,2,0),"") -> - | AI24: =VLOOKUP(Form_Responses[[#This Row],[Nombre Técnico]],'masa de trabajo'!$B:$E,3,0) -> - | AJ24: =VLOOKUP(Form_Responses[[#This Row],[Nombre Técnico]],'masa de trabajo'!$B:$E,4,0) -> -
A25: 46258.604 | B25: 7 | C25: 1-3NEATX1M | D25: JORGE LUIS REYES TOLOZA | E25: DANILO OJEDA | F25: Si | G25: Si | I25: Post Instalacion | J25: Instalacion | K25: SI | L25: Aviador bleriot 2561, Quinta Normal | N25: SI | O25: SI | P25: 5 | Q25: SI | R25: SI | S25: Alfonso Covarrubias | T25: 4 | U25: https://drive.google.com/open?id=1Y8Cfh87znZW3suakDsP6fLxmlQ9Phsz- | V25: https://drive.google.com/open?id=1uWNsEPoQ08EeVH9plTgpasLN8u23Qn5D | X25: https://drive.google.com/open?id=18AfFhcfGEXSZpB-3buXrF1NwAMcyDqaB | Y25: Si Cumple | Z25: Si Cumple | AA25: 8 | AB25: No corta pestaña y no deja tolerancia en roseta, instalación al interior por ductos, no se requiere pasa muros | AD25: SI | AE25: NO | AG25: NO | AH25: =IFERROR(VLOOKUP(Form_Responses[[#This Row],[Nombre Técnico]],'masa de trabajo'!$B:$C,2,0),"") -> SI | AI25: =VLOOKUP(Form_Responses[[#This Row],[Nombre Técnico]],'masa de trabajo'!$B:$E,3,0) -> - | AJ25: =VLOOKUP(Form_Responses[[#This Row],[Nombre Técnico]],'masa de trabajo'!$B:$E,4,0) -> -
A26: 46258.674 | B26: 7 | C26: 1-3NDSEUY5 | D26: VICTOR HUGO HUAMANI | E26: DANILO OJEDA | F26: Si | G26: Si | I26: Post Instalacion | J26: Migracion | K26: SI | L26: Pasaje 16 norte 809, Independencia | M26: NO | N26: SI | O26: NO | Q26: SI | R26: SI | S26: Miriam Antognoni cervantes | T26: 4 | U26: https://drive.google.com/open?id=1qAx-W3NPyL2fXx2ueK9w5kZj5_2GVa1W | V26: https://drive.google.com/open?id=1Ys6nt4mKfVNhwTJ1l5mGZmPtCDTs2wiD | W26: https://drive.google.com/open?id=1_rR7gN5y9InaQxMnPBe41qRYzIVGu2lO | Y26: Si Cumple | Z26: Si Cumple | AA26: 8 | AB26: Repetidor, a petición de cliente no se instala cable utp por estética servicio okey, no instala pasa muros al interior | AD26: SI | AE26: NO | AG26: NO | AH26: =IFERROR(VLOOKUP(Form_Responses[[#This Row],[Nombre Técnico]],'masa de trabajo'!$B:$C,2,0),"") -> - | AI26: =VLOOKUP(Form_Responses[[#This Row],[Nombre Técnico]],'masa de trabajo'!$B:$E,3,0) -> - | AJ26: =VLOOKUP(Form_Responses[[#This Row],[Nombre Técnico]],'masa de trabajo'!$B:$E,4,0) -> -
A27: 46260.768 | B27: 6 | C27: 1-3NDWKZA0 | D27: HECTOR SANTIS MEZA | E27: DANILO OJEDA | F27: Si | G27: Si | I27: Post Instalacion | J27: Migracion | K27: SI | L27: Emilio campodonico 6342, Quinta Normal | N27: NO | P27: 1 | Q27: SI | R27: SI | S27: Cecilia Marquez | T27: 4 | U27: https://drive.google.com/open?id=1PFip0B7ufHKKeHnUeTAxyWSdWMcEPu7- | V27: https://drive.google.com/open?id=1VREyEW1L4QF6a_uVmfAOAewpVhgupzXp | W27: https://drive.google.com/open?id=1TETN7AcbomP8by1FR1jjvR6VlAhtKclC | X27: https://drive.google.com/open?id=1m-eN6jCH8z1x3lEFlvmJ5RNYEoGDthmr | Y27: Si Cumple | Z27: Si Cumple | AA27: 9 | AB27: No retira pestaña en roseta, no gestiona repetidor de señal para aumentar producción | AD27: SI | AE27: NO | AG27: NO | AH27: =IFERROR(VLOOKUP(Form_Responses[[#This Row],[Nombre Técnico]],'masa de trabajo'!$B:$C,2,0),"") -> SI | AI27: =VLOOKUP(Form_Responses[[#This Row],[Nombre Técnico]],'masa de trabajo'!$B:$E,3,0) -> SI | AJ27: =VLOOKUP(Form_Responses[[#This Row],[Nombre Técnico]],'masa de trabajo'!$B:$E,4,0) -> -
A28: 46261.684 | B28: 10 | C28: 1-3NHP2Q99 | D28: EUDIS JESUS ALDAMA MARIN | E28: DANILO OJEDA | F28: Si | G28: Si | I28: En Conjunto con Técnico | J28: Instalacion | K28: SI | L28: Alberdi 01549 | M28: SI | N28: SI | Q28: SI | R28: SI | S28: Nicolas Nilo Jara | T28: 4 | U28: https://drive.google.com/open?id=1Srw9ivWGChc4dxUZ3qKDvzJAoXfnwUL0 | V28: https://drive.google.com/open?id=1lggRjpO-1vj3C15DfSKMfH4QeuUpD_tr | W28: https://drive.google.com/open?id=1Mevy94ij7-lC7sh8oT3i78qZD05q6nQB | X28: https://drive.google.com/open?id=1jHJg4Ti1HFMCdoVtovSQT6DcEg0-a5gp | Y28: Si Cumple | Z28: Si Cumple | AA28: 10 | AB28: Realiza instalación bajo los protocolos, uso de herramientas ambos one click correcto, retiro de pestaña en roseta okey | AC28: SI | AD28: SI | AE28: NO | AF28: SI | AG28: NO | AH28: =IFERROR(VLOOKUP(Form_Responses[[#This Row],[Nombre Técnico]],'masa de trabajo'!$B:$C,2,0),"") -> SI | AI28: =VLOOKUP(Form_Responses[[#This Row],[Nombre Técnico]],'masa de trabajo'!$B:$E,3,0) -> SI | AJ28: =VLOOKUP(Form_Responses[[#This Row],[Nombre Técnico]],'masa de trabajo'!$B:$E,4,0) -> -
A29: 46266.65 | B29: 8 | C29: 1-3NJBWJB3 | D29: VICTOR HUGO HUAMANI | E29: DANILO OJEDA | F29: Si | G29: Si | I29: En Conjunto con Técnico | J29: Instalacion | L29: General Prieto 1305, edif B dpto 1601, Independencia | M29: SI | N29: SI | Q29: SI | R29: SI | T29: 4 | U29: https://drive.google.com/open?id=1x9PfM7oe68fI1GDoXZmw6oPmH0KIs1iA | V29: https://drive.google.com/open?id=1GuCx2Pc9bbIwqE8A8sCI7z2S0TmXENSx | W29: https://drive.google.com/open?id=1IeLpHza4qeddPc7YQ_ReX0Lwwm3ry54W | X29: https://drive.google.com/open?id=1JvAgn13_aoCqozmenMDl3quKGXMoExO_ | Y29: Si Cumple | Z29: Si Cumple | AA29: 9 | AB29: No retira pestaña en roseta, no utiliza one click | AC29: No | AD29: SI | AE29: NO | AF29: SI | AG29: NO | AH29: =IFERROR(VLOOKUP(Form_Responses[[#This Row],[Nombre Técnico]],'masa de trabajo'!$B:$C,2,0),"") -> - | AI29: =VLOOKUP(Form_Responses[[#This Row],[Nombre Técnico]],'masa de trabajo'!$B:$E,3,0) -> - | AJ29: =VLOOKUP(Form_Responses[[#This Row],[Nombre Técnico]],'masa de trabajo'!$B:$E,4,0) -> -
A30: 46266.83 | B30: 9 | C30: 1-3NL4LLZO | D30: JONATHAN DIAZ CALDERON | E30: DANILO OJEDA | F30: Si | G30: Si | I30: En Conjunto con Técnico | J30: Instalacion | K30: SI | L30: Lircay 0370, Recoleta | M30: SI | N30: SI | P30: 1 | Q30: SI | R30: SI | S30: Camila Ordenes | T30: 4 | U30: https://drive.google.com/open?id=1tEudZOft8xZpMDsQSQPQeCTefP2_pegg | V30: https://drive.google.com/open?id=10Xlmjj0mBNKoHxU001e7vmmevZMvK43s | W30: https://drive.google.com/open?id=1p2tAKq4wDWPhOmNrxcjgQkRnRmLP6JL9 | X30: https://drive.google.com/open?id=142ZUGj9G7YSmqQj_PBMrNlHaoMghoHPH | Y30: Si Cumple | Z30: Si Cumple | AA30: 9 | AB30: No utiliza one click | AC30: No | AD30: SI | AE30: NO | AF30: SI | AG30: NO | AH30: =IFERROR(VLOOKUP(Form_Responses[[#This Row],[Nombre Técnico]],'masa de trabajo'!$B:$C,2,0),"") -> SI | AI30: =VLOOKUP(Form_Responses[[#This Row],[Nombre Técnico]],'masa de trabajo'!$B:$E,3,0) -> - | AJ30: =VLOOKUP(Form_Responses[[#This Row],[Nombre Técnico]],'masa de trabajo'!$B:$E,4,0) -> -
A31: 46267.696 | B31: 8 | C31: 1-3NLYBW1U | D31: HECTOR SANTIS MEZA | E31: DANILO OJEDA | F31: Si | G31: Si | I31: En Conjunto con Técnico | J31: Instalacion | K31: SI | L31: Membrillar 5728, Quinta Normal | M31: NO | N31: NO | Q31: SI | R31: SI | T31: 4 | U31: https://drive.google.com/open?id=1r0QOTrD_EHj73uRDoPT5l74DoIWcc3wT | V31: https://drive.google.com/open?id=14MxsC3C0f207VMLAOa5bWYleWv216rnN | W31: https://drive.google.com/open?id=1flZwOSfHLNBkFuA2mrKyCbnSD5a4EfU0 | X31: https://drive.google.com/open?id=1Hg3v8SkyQN2WJQTNtfEU-LeIj27gEi1X | Y31: Si Cumple | Z31: Si Cumple | AA31: 9 | AB31: A petición de cliente se instala roseta fuera de norma | AC31: SI | AD31: SI | AE31: NO | AF31: SI | AG31: NO | AH31: =IFERROR(VLOOKUP(Form_Responses[[#This Row],[Nombre Técnico]],'masa de trabajo'!$B:$C,2,0),"") -> SI | AI31: =VLOOKUP(Form_Responses[[#This Row],[Nombre Técnico]],'masa de trabajo'!$B:$E,3,0) -> SI | AJ31: =VLOOKUP(Form_Responses[[#This Row],[Nombre Técnico]],'masa de trabajo'!$B:$E,4,0) -> -
A32: 46268.671 | B32: 6 | C32: 1-3NN9AV8Q | D32: VICTOR HUGO HUAMANI | E32: DANILO OJEDA | F32: Si | G32: Si | I32: Post Instalacion | J32: Instalacion | K32: SI | L32: Pablo Urzua 1559, Independencia | M32: NO | N32: NO | Q32: SI | R32: SI | S32: Wilman Hernandez | T32: 4 | U32: https://drive.google.com/open?id=12oZ5C6nPLv6t7TKKaCG0GUD4Ii-9w7z0 | V32: https://drive.google.com/open?id=1FMERhxTFgD1yrm9IjxJ7kFwgXiUbnAg_ | W32: https://drive.google.com/open?id=1qQa-IfAV_dLOsGZNC17MNWWzKIc7SkUQ | X32: https://drive.google.com/open?id=1VBmcxDYN7guoxYGYj5s7TrynjAfkJBDw | Y32: Si Cumple | Z32: Si Cumple | AA32: 9 | AB32: A petición de cliente roseta se instala fuera de norma, si cumple con el corte en pestaña de roseta | AD32: SI | AE32: NO | AG32: NO | AH32: =IFERROR(VLOOKUP(Form_Responses[[#This Row],[Nombre Técnico]],'masa de trabajo'!$B:$C,2,0),"") -> - | AI32: =VLOOKUP(Form_Responses[[#This Row],[Nombre Técnico]],'masa de trabajo'!$B:$E,3,0) -> - | AJ32: =VLOOKUP(Form_Responses[[#This Row],[Nombre Técnico]],'masa de trabajo'!$B:$E,4,0) -> -
A33: 46269.999 | B33: 10 | C33: 1-3NNJY7KN | D33: BENJAMIN ALEJANDRO PEREZ POVEDA | E33: DANILO OJEDA | F33: Si | G33: Si | I33: En Conjunto con Técnico | J33: Reparacion | K33: SI | L33: Nueva Extremadura 5372, Quinta Normal | M33: SI | N33: SI | P33: 1 | Q33: SI | R33: SI | S33: Carlos Flores | T33: 4 | U33: https://drive.google.com/open?id=1k7NrqxzILvpaTm4qWKGA0--kvvfmIIPD | V33: https://drive.google.com/open?id=1KEgvIgqv-ptL598vs8XqqQyy3OhdPw6S | W33: https://drive.google.com/open?id=18eY7uINq6UqqU6StJ9GOuPT_sbq1-Zdo | X33: https://drive.google.com/open?id=15WtN5v6Aw0eRGykvQp2rGSm_0U6UaInr | Y33: Si Cumple | Z33: Si Cumple | AA33: 9 | AB33: No retira pestaña en roseta, utiliza herramientas de ambos one click | AC33: SI | AD33: SI | AE33: NO | AF33: SI | AG33: NO | AH33: =IFERROR(VLOOKUP(Form_Responses[[#This Row],[Nombre Técnico]],'masa de trabajo'!$B:$C,2,0),"") -> SI | AI33: =VLOOKUP(Form_Responses[[#This Row],[Nombre Técnico]],'masa de trabajo'!$B:$E,3,0) -> SI | AJ33: =VLOOKUP(Form_Responses[[#This Row],[Nombre Técnico]],'masa de trabajo'!$B:$E,4,0) -> -
A34: 46271.9 | B34: 10 | C34: 1-3ND4KOAK | D34: LUIS ROBERTO BAIGORRIA CORDOVA | E34: JULIO CABRERA | F34: Si | G34: Si | I34: En Conjunto con Técnico | J34: Instalacion | K34: SI | L34: Pasaje C 68 | M34: SI | N34: SI | O34: NO | P34: 1 | Q34: SI | R34: SI | S34: Daniela Segovia | T34: 4 | U34: https://drive.google.com/open?id=1ZHmYxeoFOC5phCiVio592U7rhVZ0tYXy | V34: https://drive.google.com/open?id=1egI1lxqhCpkbi4T4tixnLNGbMi8mvw1h | W34: https://drive.google.com/open?id=15AlcG5YugrRMwnS_TVvHf372kGJ9nrqg | X34: https://drive.google.com/open?id=1KDROq1VK7guj15eYPcVTBxTS5UbN_JpJ | Y34: Si Cumple | Z34: Si Cumple | AA34: 7 | AB34: Técnico cumple con las normas. | AC34: SI | AD34: SI | AE34: NO | AF34: SI | AG34: NO | AH34: =IFERROR(VLOOKUP(Form_Responses[[#This Row],[Nombre Técnico]],'masa de trabajo'!$B:$C,2,0),"") -> SI | AI34: =VLOOKUP(Form_Responses[[#This Row],[Nombre Técnico]],'masa de trabajo'!$B:$E,3,0) -> SI | AJ34: =VLOOKUP(Form_Responses[[#This Row],[Nombre Técnico]],'masa de trabajo'!$B:$E,4,0) -> -
A35: 46271.909 | B35: 9 | C35: 1-3NFDRCY3 | D35: LUIS ROBERTO BAIGORRIA CORDOVA | E35: JULIO CABRERA | F35: Si | G35: Si | I35: En Conjunto con Técnico | J35: Instalacion | K35: SI | L35: Cotacotani 34 | N35: SI | P35: 2 | Q35: SI | R35: SI | S35: Erick Arrue | T35: 4 | U35: https://drive.google.com/open?id=1_dnXHFhbI_rHIPquJovLBhU46yIrAZ3n | V35: https://drive.google.com/open?id=1mNdABhyD-BWi_0xnmvqaCeLnpVpDiURR | W35: https://drive.google.com/open?id=1Vk1aFMxBIdlXyYBKm1PRsmfCVwtQMPsV | X35: https://drive.google.com/open?id=1JyPmA8uNhOVvTRycpVmimBTyYoXMHg0y | Y35: Si Cumple | Z35: Si Cumple | AA35: 8 | AB35: Técnico cumple con las normas | AC35: SI | AD35: SI | AE35: NO | AF35: SI | AG35: NO | AH35: =IFERROR(VLOOKUP(Form_Responses[[#This Row],[Nombre Técnico]],'masa de trabajo'!$B:$C,2,0),"") -> SI | AI35: =VLOOKUP(Form_Responses[[#This Row],[Nombre Técnico]],'masa de trabajo'!$B:$E,3,0) -> SI | AJ35: =VLOOKUP(Form_Responses[[#This Row],[Nombre Técnico]],'masa de trabajo'!$B:$E,4,0) -> -
A36: 46271.93 | B36: 6 | C36: 1-3NEG6VRC | D36: LUIS ROBERTO BAIGORRIA CORDOVA | E36: JULIO CABRERA | F36: Si | G36: Si | I36: En Conjunto con Técnico | J36: Reparacion | L36: Las Maravillas 315 | N36: SI | O36: SI | Q36: SI | R36: SI | S36: Katherine Rodriguez | T36: 4 | U36: https://drive.google.com/open?id=1pc_PLk8xNWHcoYORgNdryoio50_OJRe6 | V36: https://drive.google.com/open?id=1wsYwrN88WDFb7NWHf8osRL8GnpzbB1e_ | X36: https://drive.google.com/open?id=16tLU2tsRGSZYpel88kvrTizbREZsrQ7x | Y36: Si Cumple | Z36: Si Cumple | AA36: 7 | AB36: Reparación reset de equipos , pruebas de cobertura test de velocidad | AD36: SI | AH36: =IFERROR(VLOOKUP(Form_Responses[[#This Row],[Nombre Técnico]],'masa de trabajo'!$B:$C,2,0),"") -> SI | AI36: =VLOOKUP(Form_Responses[[#This Row],[Nombre Técnico]],'masa de trabajo'!$B:$E,3,0) -> SI | AJ36: =VLOOKUP(Form_Responses[[#This Row],[Nombre Técnico]],'masa de trabajo'!$B:$E,4,0) -> -
A37: 46271.935 | B37: 8 | C37: 1-3NG18R4J | D37: LUIS ROBERTO BAIGORRIA CORDOVA | E37: JULIO CABRERA | F37: Si | G37: Si | I37: En Conjunto con Técnico | J37: Reparacion | L37: Carlos Pezoa Véliz 160 | N37: SI | P37: 2 | Q37: SI | R37: SI | S37: Susana Salinas | T37: 2, 4 | U37: https://drive.google.com/open?id=1cD1N6AEKr1vU2RtVlCAUekMeFW0jONZc | V37: https://drive.google.com/open?id=1LdvtDzcg_Id4QqvHWSPg28VYwtyzhbnq | X37: https://drive.google.com/open?id=1OeTk1d8S6gK4Pi9SvrmwXAB_UlGSOg3H | Y37: Si Cumple | Z37: Si Cumple | AA37: 6 | AB37: Reparación , se cambia conector cortado en roseta. | AC37: SI | AD37: SI | AF37: SI | AH37: =IFERROR(VLOOKUP(Form_Responses[[#This Row],[Nombre Técnico]],'masa de trabajo'!$B:$C,2,0),"") -> SI | AI37: =VLOOKUP(Form_Responses[[#This Row],[Nombre Técnico]],'masa de trabajo'!$B:$E,3,0) -> SI | AJ37: =VLOOKUP(Form_Responses[[#This Row],[Nombre Técnico]],'masa de trabajo'!$B:$E,4,0) -> -
A38: 46271.948 | B38: 8 | C38: 1-3NJAI727 | D38: GUERRERO LEIVA ELADIO ANDRES | E38: JULIO CABRERA | F38: Si | G38: Si | I38: En Conjunto con Técnico | J38: Reparacion | L38: Pasaje E 32 | N38: SI | Q38: SI | R38: SI | S38: Jorge Caamaño | T38: 4 | U38: https://drive.google.com/open?id=1KCRYVed39OkGvsCk0Um8ai5Fp51O9jAO | V38: https://drive.google.com/open?id=1qfFagTsqYMPvdSUFin5YtdOKQ0tlmQiT | X38: https://drive.google.com/open?id=1isoAII7ef9vNpSjclPMVQR5qOtG59WxP | Y38: Si Cumple | Z38: Si Cumple | AA38: 8 | AB38: Reparación drop levantado en CTO. | AC38: SI | AD38: SI | AF38: SI | AH38: =IFERROR(VLOOKUP(Form_Responses[[#This Row],[Nombre Técnico]],'masa de trabajo'!$B:$C,2,0),"") -> - | AI38: =VLOOKUP(Form_Responses[[#This Row],[Nombre Técnico]],'masa de trabajo'!$B:$E,3,0) -> - | AJ38: =VLOOKUP(Form_Responses[[#This Row],[Nombre Técnico]],'masa de trabajo'!$B:$E,4,0) -> -
A39: 46271.956 | B39: 7 | C39: 1-3NNEKWHY | D39: HECTOR DAVID REYES OLMOS | E39: JULIO CABRERA | F39: Si | G39: Si | I39: En Conjunto con Técnico | J39: Instalacion | L39: Parinacota 50 depto 21 | N39: SI | P39: 1 | Q39: SI | R39: SI | S39: Mama de titular | T39: 3 | U39: https://drive.google.com/open?id=14SFHycDeSjKPiGhW0C0rxgm3MRz-nqXT | V39: https://drive.google.com/open?id=1knpkTpAujRFTgyyCdsXBosb0UgOFoN2E | W39: https://drive.google.com/open?id=1wFF803e-lPpln5LWOzqcWBALjxkJ23cK | X39: https://drive.google.com/open?id=1MwSEkrsBBQvBBAIH6sUjmiE0-F2pEfCp | Y39: Si Cumple | Z39: No Cumple | AA39: 5 | AB39: Instalación , técnico reutiliza drop a petición de cliente el dormitorio lo había forrado palmetas de pluma voy con diseños. | AC39: SI | AD39: SI | AE39: SI | AF39: SI | AH39: =IFERROR(VLOOKUP(Form_Responses[[#This Row],[Nombre Técnico]],'masa de trabajo'!$B:$C,2,0),"") -> - | AI39: =VLOOKUP(Form_Responses[[#This Row],[Nombre Técnico]],'masa de trabajo'!$B:$E,3,0) -> - | AJ39: =VLOOKUP(Form_Responses[[#This Row],[Nombre Técnico]],'masa de trabajo'!$B:$E,4,0) -> -
A40: 46271.964 | B40: 8 | C40: 1-3N7Q47LB | D40: JUAN PABLO CACERES SOBARZO | E40: JULIO CABRERA | F40: Si | G40: Si | I40: En Conjunto con Técnico | J40: Instalacion | L40: Los Limonares 399 casa 19 | N40: SI | Q40: SI | R40: SI | S40: Armando Aravena | T40: 4 | U40: https://drive.google.com/open?id=1ifMagLDjS7-z44QC25L9EwxBgIJHujRK | V40: https://drive.google.com/open?id=15udke8hsV9VTpZEmGDtbrUO7CrcGQMlP | W40: https://drive.google.com/open?id=1vmgil_WaQ0xuPdmdkg1EXsUweEWPvmfe | X40: https://drive.google.com/open?id=17dCwfUXA9AI7eeNFUBE4rabzbj9TBekH | Y40: Si Cumple | Z40: Si Cumple | AA40: 8 | AB40: Instalación por cámaras. | AC40: SI | AD40: SI | AE40: NO | AF40: SI | AG40: NO | AH40: =IFERROR(VLOOKUP(Form_Responses[[#This Row],[Nombre Técnico]],'masa de trabajo'!$B:$C,2,0),"") -> - | AI40: =VLOOKUP(Form_Responses[[#This Row],[Nombre Técnico]],'masa de trabajo'!$B:$E,3,0) -> - | AJ40: =VLOOKUP(Form_Responses[[#This Row],[Nombre Técnico]],'masa de trabajo'!$B:$E,4,0) -> -
...

Sheet masa de trabajo
B1: Nombre Técnico | C1: Se llevó a cabo la mesa de trabajo. | D1: Se cerró el proceso con el técnico? | E1: Observaciones
B2: LUIS ROBERTO BAIGORRIA CORDOVA | C2: SI | D2: SI | E2: -
B3: MARCO ALEXANDER BENITEZ FERNANDEZ | C3: - | D3: - | E3: -
B4: BRAULIO DANILO DIAZ CORNEJO | C4: SI | D4: SI | E4: -
B5: ANDRES EDUARDO RODRIGUEZ BERMEDO | C5: - | D5: - | E5: -
B6: ANDRES EDUARDO RODRIGUEZ BERMEDO | C6: - | D6: - | E6: -
B7: JUAN PABLO CACERES SOBARZO | C7: - | D7: - | E7: -
B8: MARIN ORELLANA HERNAN TOMAS | C8: - | D8: - | E8: -
B9: ANDRES EDUARDO RODRIGUEZ BERMEDO | C9: - | D9: - | E9: -
B10: LUIS ROBERTO BAIGORRIA CORDOVA | C10: SI | D10: SI | E10: -
B11: VICTOR HUGO HUAMANI | C11: - | D11: - | E11: -
B12: LUIS ROBERTO BAIGORRIA CORDOVA | C12: - | D12: - | E12: -
... B39: BENJAMIN ALEJANDRO PEREZ POVEDA | C39: SI | D39: - | E39: -
